<?xml version="1.0" ?>
<!-- =================================================================================== -->
<!-- |    This document was autogenerated by xacro from src/kinova-ros/kinova_description/urdf/j2s7s300_standalone.xacro | -->
<!-- |    EDITING THIS FILE BY HAND IS NOT RECOMMENDED                                 | -->
<!-- =================================================================================== -->
<!-- j2s7s300 refers to jaco v2 7DOF spherical 3fingers -->
<robot name="j2s7s300" xmlns:body="http://playerstage.sourceforge.net/gazebo/xmlschema/#body" xmlns:controller="http://playerstage.sourceforge.net/gazebo/xmlschema/#controller" xmlns:gazebo="http://playerstage.sourceforge.net/gazebo/xmlschema/#gz" xmlns:geom="http://playerstage.sourceforge.net/gazebo/xmlschema/#geom" xmlns:interface="http://playerstage.sourceforge.net/gazebo/xmlschema/#interface" xmlns:joint="http://playerstage.sourceforge.net/gazebo/xmlschema/#joint" xmlns:model="http://playerstage.sourceforge.net/gazebo/xmlschema/#model" xmlns:physics="http://playerstage.sourceforge.net/gazebo/xmlschema/#physics" xmlns:renderable="http://playerstage.sourceforge.net/gazebo/xmlschema/#renderable" xmlns:rendering="http://playerstage.sourceforge.net/gazebo/xmlschema/#rendering" xmlns:sensor="http://playerstage.sourceforge.net/gazebo/xmlschema/#sensor" xmlns:xacro="http://ros.org/wiki/xacro" xmlns:xi="http://www.w3.org/2001/XInclude">
  <!-- links      		mesh_no
   base           		0
   shoulder       		1
   arm            		2
   forearm        		3
   wrist          		4
   arm_mico       		5
   arm_half1 (7dof)		6
   arm_half2 (7dof)		7
   wrist_spherical_1  8
   wrist_spherical_2  9

   hand 3 finger  		55
   hand_2finger   		56
   finger_proximal		57
   finger_distal      58
-->
  <!-- links      		mesh_no
   base           		0
   shoulder       		1
   arm            		2
   forearm        		3
   wrist          		4
   arm_mico       		5
   arm_half1 (7dof)		6
   arm_half2 (7dof)		7
   wrist_spherical_1  8
   wrist_spherical_2  9

   hand 3 finger  		55
   hand_2finger   		56
   finger_proximal		57
   finger_distal      58
-->

  <link name="j2s7s300_link_base">
    <visual>
      <geometry>
        <mesh filename="package://kinova_description/meshes/base.dae"/>
      </geometry>
      <material name="carbon_fiber">
        <color rgba="0.792156862745098 0.819607843137255 0.933333333333333 1"/>
      </material>
    </visual>
    <collision>
      <geometry>
        <mesh filename="package://kinova_description/meshes/base.dae"/>
      </geometry>
    </collision>
    <inertial>
      <mass value="0.46784"/>
      <origin rpy="0 0 0" xyz="0 0 0.1255"/>
      <inertia ixx="0.000951270861568" ixy="0" ixz="0" iyy="0.000951270861568" iyz="0" izz="0.000374272"/>
    </inertial>
  </link>
  <link name="j2s7s300_link_1">
    <visual>
      <geometry>
        <mesh filename="package://kinova_description/meshes/shoulder.dae"/>
      </geometry>
      <material name="carbon_fiber">
        <color rgba="0.792156862745098 0.819607843137255 0.933333333333333 1"/>
      </material>
    </visual>
    <visual>
      <geometry>
        <mesh filename="package://kinova_description/meshes/ring_big.STL"/>
      </geometry>
    </visual>
    <collision>
      <geometry>
        <mesh filename="package://kinova_description/meshes/shoulder.dae"/>
      </geometry>
    </collision>
    <inertial>
      <mass value="0.7477"/>
      <origin xyz="0 -0.002 -0.0605"/>
      <inertia ixx="0.00152031725204" ixy="0" ixz="0" iyy="0.00152031725204" iyz="0" izz="0.00059816"/>
    </inertial>
  </link>
  <joint name="j2s7s300_joint_1" type="continuous">
    <parent link="j2s7s300_link_base"/>
    <child link="j2s7s300_link_1"/>
    <axis xyz="0 0 1"/>
    <limit effort="2000" lower="-6.28318530718" upper="6.28318530718" velocity="1"/>
    <origin rpy="0 3.14159265359 0" xyz="0 0 0.15675"/>
    <dynamics damping="0.0" friction="0.0"/>
  </joint>
  <link name="j2s7s300_link_2">
    <visual>
      <geometry>
        <mesh filename="package://kinova_description/meshes/arm_half_1.dae"/>
      </geometry>
      <material name="carbon_fiber">
        <color rgba="0.792156862745098 0.819607843137255 0.933333333333333 1"/>
      </material>
    </visual>
    <visual>
      <geometry>
        <mesh filename="package://kinova_description/meshes/ring_big.STL"/>
      </geometry>
    </visual>
    <collision>
      <geometry>
        <mesh filename="package://kinova_description/meshes/arm_half_1.dae"/>
      </geometry>
    </collision>
    <inertial>
      <mass value="0.8447"/>
      <origin xyz="0 -0.103563213 0"/>
      <inertia ixx="0.00247073761701" ixy="0" ixz="0" iyy="0.000380115" iyz="0" izz="0.00247073761701"/>
    </inertial>
  </link>
  <joint name="j2s7s300_joint_2" type="revolute">
    <parent link="j2s7s300_link_1"/>
    <child link="j2s7s300_link_2"/>
    <axis xyz="0 0 1"/>
    <limit effort="2000" lower="0.523598775598" upper="5.75958653158" velocity="1"/>
    <origin rpy="-1.57079632679 0 3.14159265359" xyz="0 0.0016 -0.11875"/>
    <dynamics damping="0.0" friction="0.0"/>
  </joint>
  <link name="j2s7s300_link_3">
    <visual>
      <geometry>
        <mesh filename="package://kinova_description/meshes/arm_half_2.dae"/>
      </geometry>
      <material name="carbon_fiber">
        <color rgba="0.792156862745098 0.819607843137255 0.933333333333333 1"/>
      </material>
    </visual>
    <visual>
      <geometry>
        <mesh filename="package://kinova_description/meshes/ring_big.STL"/>
      </geometry>
    </visual>
    <collision>
      <geometry>
        <mesh filename="package://kinova_description/meshes/arm_half_2.dae"/>
      </geometry>
    </collision>
    <inertial>
      <mass value="0.8447"/>
      <origin xyz="0 0 -0.1022447445"/>
      <inertia ixx="0.00247073761701" ixy="0" ixz="0" iyy="0.00247073761701" iyz="0" izz="0.000380115"/>
    </inertial>
  </link>
  <joint name="j2s7s300_joint_3" type="continuous">
    <parent link="j2s7s300_link_2"/>
    <child link="j2s7s300_link_3"/>
    <axis xyz="0 0 1"/>
    <limit effort="2000" lower="-6.28318530718" upper="6.28318530718" velocity="1"/>
    <origin rpy="-1.57079632679 0 0" xyz="0 -0.205 0"/>
    <dynamics damping="0.0" friction="0.0"/>
  </joint>
  <link name="j2s7s300_link_4">
    <visual>
      <geometry>
        <mesh filename="package://kinova_description/meshes/forearm.dae"/>
      </geometry>
      <material name="carbon_fiber">
        <color rgba="0.792156862745098 0.819607843137255 0.933333333333333 1"/>
      </material>
    </visual>
    <visual>
      <geometry>
        <mesh filename="package://kinova_description/meshes/ring_small.STL"/>
      </geometry>
    </visual>
    <collision>
      <geometry>
        <mesh filename="package://kinova_description/meshes/forearm.dae"/>
      </geometry>
    </collision>
    <inertial>
      <mass value="0.6763"/>
      <origin xyz="0 0.081 -0.0086"/>
      <inertia ixx="0.00142022431908" ixy="0" ixz="0" iyy="0.000304335" iyz="0" izz="0.00142022431908"/>
    </inertial>
  </link>
  <joint name="j2s7s300_joint_4" type="revolute">
    <parent link="j2s7s300_link_3"/>
    <child link="j2s7s300_link_4"/>
    <axis xyz="0 0 1"/>
    <limit effort="2000" lower="0.523598775598" upper="5.75958653158" velocity="1"/>
    <origin rpy="1.57079632679 0 3.14159265359" xyz="0 0 -0.205"/>
    <dynamics damping="0.0" friction="0.0"/>
  </joint>
  <link name="j2s7s300_link_5">
    <visual>
      <geometry>
        <mesh filename="package://kinova_description/meshes/wrist_spherical_1.dae"/>
      </geometry>
      <material name="carbon_fiber">
        <color rgba="0.792156862745098 0.819607843137255 0.933333333333333 1"/>
      </material>
    </visual>
    <visual>
      <geometry>
        <mesh filename="package://kinova_description/meshes/ring_small.STL"/>
      </geometry>
    </visual>
    <collision>
      <geometry>
        <mesh filename="package://kinova_description/meshes/wrist_spherical_1.dae"/>
      </geometry>
    </collision>
    <inertial>
      <mass value="0.463"/>
      <origin xyz="0 0.0028848942 -0.0541932613"/>
      <inertia ixx="0.0004321316048" ixy="0" ixz="0" iyy="0.0004321316048" iyz="0" izz="9.26e-05"/>
    </inertial>
  </link>
  <joint name="j2s7s300_joint_5" type="continuous">
    <parent link="j2s7s300_link_4"/>
    <child link="j2s7s300_link_5"/>
    <axis xyz="0 0 1"/>
    <limit effort="2000" lower="-6.28318530718" upper="6.28318530718" velocity="1"/>
    <origin rpy="-1.57079632679 0 3.14159265359" xyz="0 0.2073 -0.0114"/>
    <dynamics damping="0.0" friction="0.0"/>
  </joint>
  <link name="j2s7s300_link_6">
    <visual>
      <geometry>
        <mesh filename="package://kinova_description/meshes/wrist_spherical_2.dae"/>
      </geometry>
      <material name="carbon_fiber">
        <color rgba="0.792156862745098 0.819607843137255 0.933333333333333 1"/>
      </material>
    </visual>
    <visual>
      <geometry>
        <mesh filename="package://kinova_description/meshes/ring_small.STL"/>
      </geometry>
    </visual>
    <collision>
      <geometry>
        <mesh filename="package://kinova_description/meshes/wrist_spherical_2.dae"/>
      </geometry>
    </collision>
    <inertial>
      <mass value="0.463"/>
      <origin xyz="0 0.0497208855 -0.0028562765"/>
      <inertia ixx="0.0004321316048" ixy="0" ixz="0" iyy="9.26e-05" iyz="0" izz="0.0004321316048"/>
    </inertial>
  </link>
  <joint name="j2s7s300_joint_6" type="revolute">
    <parent link="j2s7s300_link_5"/>
    <child link="j2s7s300_link_6"/>
    <axis xyz="0 0 1"/>
    <limit effort="2000" lower="0.523598775598" upper="5.75958653158" velocity="1"/>
    <origin rpy="1.57079632679 0 3.14159265359" xyz="0 0 -0.10375"/>
    <dynamics damping="0.0" friction="0.0"/>
  </joint>
  <link name="j2s7s300_link_7">
    <visual>
      <geometry>
        <mesh filename="package://kinova_description/meshes/hand_3finger.dae"/>
      </geometry>
      <material name="carbon_fiber">
        <color rgba="0.792156862745098 0.819607843137255 0.933333333333333 1"/>
      </material>
    </visual>
    <visual>
      <geometry>
        <mesh filename="package://kinova_description/meshes/ring_small.STL"/>
      </geometry>
    </visual>
    <collision>
      <geometry>
        <mesh filename="package://kinova_description/meshes/hand_3finger.dae"/>
      </geometry>
    </collision>
    <inertial>
      <mass value="0.727"/>
      <origin xyz="0 0 -0.06"/>
      <inertia ixx="0.0003453236187" ixy="0" ixz="0" iyy="0.0003453236187" iyz="0" izz="0.0005816"/>
    </inertial>
  </link>
  <joint name="j2s7s300_joint_7" type="continuous">
    <parent link="j2s7s300_link_6"/>
    <child link="j2s7s300_link_7"/>
    <axis xyz="0 0 1"/>
    <limit effort="2000" lower="-6.28318530718" upper="6.28318530718" velocity="1"/>
    <origin rpy="-1.57079632679 0 3.14159265359" xyz="0 0.10375 0"/>
    <dynamics damping="0.0" friction="0.0"/>
  </joint>
  <link name="j2s7s300_end_effector">
    <visual>
      <geometry>
        <box size="0 0 0"/>
      </geometry>
    </visual>
    <collision>
      <geometry>
        <box size="0 0 0"/>
      </geometry>
    </collision>
  </link>
  <joint name="j2s7s300_joint_end_effector" type="fixed">
    <parent link="j2s7s300_link_7"/>
    <child link="j2s7s300_end_effector"/>
    <axis xyz="0 0 0"/>
    <limit effort="2000" lower="0" upper="0" velocity="1"/>
    <origin rpy="3.14159265359 0 0" xyz="0 0 -0.1600"/>
  </joint>
</robot>
